<mujoco model="cheetah">
  <compiler angle="radian" coordinate="local" inertiafromgeom="true" settotalmass="7"/> <!-- Reduced mass by 50% -->
  <default>
    <joint armature=".05" damping=".005" limited="true" solimplimit="0 .8 .03" solreflimit=".02 1" stiffness="4"/> <!-- Reduced joint parameters -->
    <geom conaffinity="0" condim="3" contype="1" friction=".4 .1 .1" rgba="0.8 0.6 .4 1" solimp="0.0 0.8 0.01" solref="0.02 1"/>
    <motor ctrllimited="true" ctrlrange="-1 1"/>
  </default>
  <size nstack="300000" nuser_geom="1"/>
  <option gravity="0 0 -9.81" timestep="0.01"/>
  <asset>
    <texture builtin="gradient" height="100" rgb1="1 1 1" rgb2="0 0 0" type="skybox" width="100"/>
    <texture builtin="flat" height="1278" mark="cross" markrgb="1 1 1" name="texgeom" random="0.01" rgb1="0.8 0.6 0.4" rgb2="0.8 0.6 0.4" type="cube" width="127"/>
    <texture builtin="checker" height="100" name="texplane" rgb1="0 0 0" rgb2="0.8 0.8 0.8" type="2d" width="100"/>
    <material name="MatPlane" reflectance="0.5" shininess="1" specular="1" texrepeat="60 60" texture="texplane"/>
    <material name="geom" texture="texgeom" texuniform="true"/>
  </asset>
  <worldbody>
    <light cutoff="100" diffuse="1 1 1" dir="-0 0 -1.3" directional="true" exponent="1" pos="0 0 1.3" specular=".1 .1 .1"/>
    <geom conaffinity="1" condim="3" material="MatPlane" name="floor" pos="0 0 0" rgba="0.8 0.9 0.8 1" size="40 40 40" type="plane"/>
    <body name="torso_1" pos="0 0 .35"> <!-- Adjusted initial height -->
      <camera name="track" mode="trackcom" pos="0 -1.5 0.15" xyaxes="1 0 0 0 0 1"/> <!-- Adjusted camera position -->
      <joint armature="0" axis="1 0 0" damping="0" limited="false" name="rootx" pos="0 0 0" stiffness="0" type="slide"/>
      <joint armature="0" axis="0 0 1" damping="0" limited="false" name="rootz" pos="0 0 0" stiffness="0" type="slide"/>
      <joint armature="0" axis="0 1 0" damping="0" limited="false" name="rooty" pos="0 0 0" stiffness="0" type="hinge"/>
      <geom fromto="-0.125 0 0 -0.05 0 0" name="torso_1" size="0.023" type="capsule"/> <!-- Scaled down dimensions -->

      <!-- Back legs -->
      <body name="back_legs" pos="-0.125 0 0"> <!-- Adjusted position -->
        <!-- Left back leg -->
        <body name="lbthigh" pos="0 0.05 0"> <!-- Adjusted position -->
          <joint axis="0 1 0" damping="2.25" name="lbthigh" pos="0 0 0" range="-1 .7" stiffness="90" type="hinge"/> <!-- Adjusted parameters -->
          <geom axisangle="0 1 0 .52" name="lbthigh" pos="-.035 0 -.06" size="0.023 .0665" type="capsule"/> <!-- Scaled down dimensions -->
          <body name="lbshin" pos="-.07 0 -.12"> <!-- Adjusted position -->
            <joint axis="0 1 0" damping="1.5" name="lbshin" pos="0 0 0" range="-1.2 .87" stiffness="60" type="hinge"/> <!-- Adjusted parameters -->
            <geom axisangle="0 1 0 -.6" name="lbshin" pos=".0325 0 -.045" rgba="0.9 0.6 0.6 1" size="0.023 .053" type="capsule"/> <!-- Scaled down dimensions -->
          </body>
        </body>

        <!-- Right back leg (similarly adjusted) -->
        <body name="rbthigh" pos="0 -0.05 0">
          <joint axis="0 1 0" damping="2.25" name="rbthigh" pos="0 0 0" range="-1 .7" stiffness="90" type="hinge"/>
          <geom axisangle="0 1 0 .52" name="rbthigh" pos="-.035 0 -.06" size="0.023 .0665" type="capsule"/>
          <body name="rbshin" pos="-.07 0 -.12">
            <joint axis="0 1 0" damping="1.5" name="rbshin" pos="0 0 0" range="-1.2 .87" stiffness="60" type="hinge"/>
            <geom axisangle="0 1 0 -.6" name="rbshin" pos=".0325 0 -.045" rgba="0.9 0.6 0.6 1" size="0.023 .053" type="capsule"/>
          </body>
        </body>

      <body name="torso_2" pos=".125 0 0"> <!-- Adjusted position -->
        <joint axis="0 1 0" name="torso_joint_1" pos="0 0 0" range="0. 1.0" stiffness="25" type="hinge"/> <!-- Adjusted stiffness -->
        <geom fromto="-0.025 0 0 .075 0 0" name="torso_2" size="0.023" type="capsule"/> <!-- Scaled down dimensions -->
        
        <body name="torso_3" pos=".125 0 0"> <!-- Adjusted position -->
          <joint axis="0 1 0" name="torso_joint_2" pos="0 0 0" range="0. 1.0" stiffness="25" type="hinge"/> <!-- Adjusted stiffness -->
          <geom fromto="-0.025 0 0 .075 0 0" name="torso_3" size="0.023" type="capsule"/> <!-- Scaled down dimensions -->
          
          <body name="torso_4" pos=".125 0 0"> <!-- Adjusted position -->
            <joint axis="0 1 0" name="torso_joint_3" pos="0 0 0" range="0. 1.0" stiffness="25" type="hinge"/> <!-- Adjusted stiffness -->
            <geom fromto="-0.025 0 0 .075 0 0" name="torso_4" size="0.023" type="capsule"/> <!-- Scaled down dimensions -->
            <geom axisangle="0 1 0 .87" name="head" pos=".15 0 .05" size="0.023 .075" type="capsule"/> <!-- Scaled down dimensions -->

            <!-- Front legs -->
            <body name="front_legs" pos="0.075 0 0"> <!-- Adjusted position -->
              <!-- Left front leg (similarly adjusted) -->
              <body name="lfthigh" pos="0 0.05 0">
                <joint axis="0 1 0" damping="2.25" name="lfthigh" pos="0 0 0" range="-1 .7" stiffness="90" type="hinge"/>
                <geom axisangle="0 1 0 .52" name="lfthigh" pos="-.035 0 -.06" size="0.023 .0665" type="capsule"/>
                <body name="lfshin" pos="-.07 0 -.12">
                  <joint axis="0 1 0" damping="1.5" name="lfshin" pos="0 0 0" range="-1.2 .87" stiffness="60" type="hinge"/>
                  <geom axisangle="0 1 0 -.6" name="lfshin" pos=".0325 0 -.045" rgba="0.9 0.6 0.6 1" size="0.023 .053" type="capsule"/>
                </body>
              </body>

              <!-- Right front leg (similarly adjusted) -->
              <body name="rfthigh" pos="0 -0.05 0">
                <joint axis="0 1 0" damping="2.25" name="rfthigh" pos="0 0 0" range="-1 .7" stiffness="90" type="hinge"/>
                <geom axisangle="0 1 0 .52" name="rfthigh" pos="-.035 0 -.06" size="0.023 .0665" type="capsule"/>
                <body name="rfshin" pos="-.07 0 -.12">
                  <joint axis="0 1 0" damping="1.5" name="rfshin" pos="0 0 0" range="-1.2 .87" stiffness="60" type="hinge"/>
                  <geom axisangle="0 1 0 -.6" name="rfshin" pos=".0325 0 -.045" rgba="0.9 0.6 0.6 1" size="0.023 .053" type="capsule"/>
                </body>
              </body>
            </body>
            </body>
          </body>
        </body>
      </body>
    </body>
  </worldbody>

  <actuator>
    <!-- Leg actuators (adjusted gear ratios) -->
    <motor gear="60" joint="lfthigh" name="lfthigh"/>
    <motor gear="30" joint="lfshin" name="lfshin"/>
    <motor gear="60" joint="rfthigh" name="rfthigh"/>
    <motor gear="30" joint="rfshin" name="rfshin"/>
    <motor gear="60" joint="lbthigh" name="lbthigh"/>
    <motor gear="45" joint="lbshin" name="lbshin"/>
    <motor gear="60" joint="rbthigh" name="rbthigh"/>
    <motor gear="45" joint="rbshin" name="rbshin"/>
  </actuator>
</mujoco>