<mujoco model="cheetah">
  <compiler angle="radian" coordinate="local" inertiafromgeom="true"/> <!-- Reduced mass by 50% -->
  <default>
    <joint armature=".05" damping=".005" limited="true" solimplimit="0 .8 .03" solreflimit=".02 1" stiffness="4"/> <!-- Reduced joint parameters -->
    <geom conaffinity="0" condim="3" contype="1" friction=".4 .1 .1" rgba="0.8 0.6 .4 1" solimp="0.0 0.8 0.01" solref="0.02 1"/>
    <!-- <motor ctrllimited="true" ctrlrange="-1 1"/> -->
  </default>

  <size nstack="300000" nuser_geom="1"/>
  <option gravity="0 0 -9.81" timestep="0.01"/>

  <asset>
    <texture builtin="gradient" height="100" rgb1="1 1 1" rgb2="0 0 0" type="skybox" width="100"/>
    <texture builtin="flat" height="1278" mark="cross" markrgb="1 1 1" name="texgeom" random="0.01" rgb1="0.8 0.6 0.4" rgb2="0.8 0.6 0.4" type="cube" width="127"/>
    <texture builtin="checker" height="100" name="texplane" rgb1="0 0 0" rgb2="0.8 0.8 0.8" type="2d" width="100"/>
    <material name="MatPlane" reflectance="0.5" shininess="1" specular="1" texrepeat="60 60" texture="texplane"/>
    <material name="geom" texture="texgeom" texuniform="true"/>
  </asset>

  <worldbody>
    <light cutoff="100" diffuse="1 1 1" dir="-0 0 -1.3" directional="true" exponent="1" pos="0 0 1.3" specular=".1 .1 .1"/>
    <geom conaffinity="1" condim="3" material="MatPlane" name="floor" pos="0 0 0" rgba="0.8 0.9 0.8 1" size="40 40 40" type="plane"/>
    <body name="torso_1" pos="0 0 .35"> <!-- Adjusted initial height -->
      <camera name="track" mode="trackcom" pos="0 -1.5 0.15" xyaxes="1 0 0 0 0 1"/> <!-- Adjusted camera position -->
      <joint armature="0" axis="1 0 0" damping="0" limited="false" name="rootx" pos="0 0 0" stiffness="0" type="slide"/>
      <joint armature="0" axis="0 0 1" damping="0" limited="false" name="rootz" pos="0 0 0" stiffness="0" type="slide"/>
      <joint armature="0" axis="0 1 0" damping="0" limited="false" name="rooty" pos="0 0 0" stiffness="0" type="hinge"/>
      <inertial pos="0 0 0" mass="0.114"/>
      <geom fromto="-0.125 0 0 -0.05 0 0" name="torso_1" size="0.023" type="capsule"/> <!-- Scaled down dimensions -->
      <site name="imu_site" pos="0 0 0" rgba="1 0 0 1" size="0.02 0.02 0.02" type="box"/>
      <!-- <joint axis="0 1 0" damping="2.25" name="back_legs_joint" pos="-0.125 0 0" range="-0.1 0.0" stiffness="5" type="hinge"/> -->
      <!-- Back legs -->
      <body name="back_legs" pos="-0.125 0 0"> <!-- Adjusted position -->
        <inertial pos="0 0 0" mass="1.6"/>
        <!-- Left back leg -->
        <body name="lbthigh" pos="0 0.05 0"> <!-- Adjusted position -->
          <joint axis="0 1 0" damping="2.25" name="lbthigh" pos="0 0 0" range="-1 .7" stiffness="10" type="hinge"/> <!-- Adjusted parameters -->
          <inertial pos="0 0 0" mass="0.2"/>
          <geom axisangle="0 1 0 .52" name="lbthigh" pos="-.035 0 -.06" size="0.023 .0665" type="capsule"/> <!-- Scaled down dimensions -->
          <body name="lbshin" pos="-.07 0 -.12"> <!-- Adjusted position -->
            <joint axis="0 1 0" damping="1.5" name="lbshin" pos="0 0 0" range="-1.2 .87" stiffness="10" type="hinge"/> <!-- Adjusted parameters -->
            <inertial pos="0 0 0" mass="0.2"/>
            <geom axisangle="0 1 0 -.6" name="lbshin" pos=".0325 0 -.045" rgba="0.9 0.6 0.6 1" size="0.023 .053" type="capsule"/> <!-- Scaled down dimensions -->
          </body>
        </body>

        <!-- Right back leg (similarly adjusted) -->
        <body name="rbthigh" pos="0 -0.05 0">
          <joint axis="0 1 0" damping="2.25" name="rbthigh" pos="0 0 0" range="-1 .7" stiffness="10" type="hinge"/>
          <inertial pos="0 0 0" mass="0.2"/>
          <geom axisangle="0 1 0 .52" name="rbthigh" pos="-.035 0 -.06" size="0.023 .0665" type="capsule"/>
          <body name="rbshin" pos="-.07 0 -.12">
            <inertial pos="0 0 0" mass="0.2"/>
            <joint axis="0 1 0" damping="1.5" name="rbshin" pos="0 0 0" range="-1.2 .87" stiffness="10" type="hinge"/>
            <geom axisangle="0 1 0 -.6" name="rbshin" pos=".0325 0 -.045" rgba="0.9 0.6 0.6 1" size="0.023 .053" type="capsule"/>
          </body>
        </body>

      <body name="torso_2" pos=".125 0 0"> <!-- Adjusted position -->
        <joint axis="0 1 0" name="torso_joint_1" pos="0 0 0" range="-0.2 0.5" stiffness="50" type="hinge"/> <!-- Adjusted stiffness -->
        <inertial pos="0 0 0" mass="0.1529"/>
        <geom fromto="-0.025 0 0 .075 0 0" name="torso_2" size="0.023" type="capsule"/> <!-- Scaled down dimensions -->
        
        <body name="torso_3" pos=".125 0 0"> <!-- Adjusted position -->
          <joint axis="0 1 0" name="torso_joint_2" pos="0 0 0" range="-0.2 0.5" stiffness="50" type="hinge"/> <!-- Adjusted stiffness -->
          <inertial pos="0 0 0" mass="0.1529"/>
          <geom fromto="-0.025 0 0 .075 0 0" name="torso_3" size="0.023" type="capsule"/> <!-- Scaled down dimensions -->
          
          <body name="torso_4" pos=".125 0 0"> <!-- Adjusted position -->
            <joint axis="0 1 0" name="torso_joint_3" pos="0 0 0" range="-0.2 0.5" stiffness="50" type="hinge"/> <!-- Adjusted stiffness -->
            <inertial pos="0 0 0" mass="0.38225"/>
            <geom fromto="-0.025 0 0 .075 0 0" name="torso_4" size="0.023" type="capsule"/> <!-- Scaled down dimensions -->
            <geom axisangle="0 1 0 .87" name="head" pos=".15 0 .05" size="0.023 .075" type="capsule"/> <!-- Scaled down dimensions -->
            <!-- <joint axis="0 1 0" damping="2.25" name="front_legs_joint" pos=".15 0 0" range="0.0 0.1" stiffness="10" type="hinge"/> -->
            <!-- Front legs -->
            <body name="front_legs" pos="0.075 0 0"> <!-- Adjusted position -->
              <!-- Left front leg (similarly adjusted) -->
              <inertial pos="0 0 0" mass="1.6"/>
              <body name="lfthigh" pos="0 0.05 0">
                <joint axis="0 1 0" damping="2.25" name="lfthigh" pos="0 0 0" range="-1 .7" stiffness="10" type="hinge"/>
                <inertial pos="0 0 0" mass="0.2"/>
                <geom axisangle="0 1 0 .52" name="lfthigh" pos="-.035 0 -.06" size="0.023 .0665" type="capsule"/>
                <body name="lfshin" pos="-.07 0 -.12">
                  <joint axis="0 1 0" damping="1.5" name="lfshin" pos="0 0 0" range="-1.2 .87" stiffness="10" type="hinge"/>
                  <inertial pos="0 0 0" mass="0.2"/>
                  <geom axisangle="0 1 0 -.6" name="lfshin" pos=".0325 0 -.045" rgba="0.9 0.6 0.6 1" size="0.023 .053" type="capsule"/>
                </body>
              </body>

              <!-- Right front leg (similarly adjusted) -->
              <body name="rfthigh" pos="0 -0.05 0">
                <joint axis="0 1 0" damping="2.25" name="rfthigh" pos="0 0 0" range="-1 .7" stiffness="10" type="hinge"/>
                <inertial pos="0 0 0" mass="0.2"/>
                <geom axisangle="0 1 0 .52" name="rfthigh" pos="-.035 0 -.06" size="0.023 .0665" type="capsule"/>
                <body name="rfshin" pos="-.07 0 -.12">
                  <joint axis="0 1 0" damping="1.5" name="rfshin" pos="0 0 0" range="-1.2 .87" stiffness="10" type="hinge"/>
                  <inertial pos="0 0 0" mass="0.2"/>
                  <geom axisangle="0 1 0 -.6" name="rfshin" pos=".0325 0 -.045" rgba="0.9 0.6 0.6 1" size="0.023 .053" type="capsule"/>
                </body>
              </body>
            </body>
            </body>
          </body>
        </body>
      </body>
    </body>
  </worldbody>

  <sensor>
    <accelerometer name="accelerometer" site="imu_site"/>
    <gyro name="gyro" site="imu_site"/>
  </sensor>

  <actuator>
    <!-- Leg actuators (adjusted gear ratios) -->
    <!-- <motor name="lfthigh" joint="lfthigh" gear="6" ctrlrange="-1 1" forcerange="-2.83 2.83" />
    <motor name="lfshin" joint="lfshin" gear="6" ctrlrange="-1 1" forcerange="-2.83 2.83" />
    <motor name="rfthigh" joint="rfthigh" gear="6" ctrlrange="-1 1" forcerange="-2.83 2.83" />
    <motor name="rfshin" joint="rfshin" gear="6" ctrlrange="-1 1" forcerange="-2.83 2.83" />
    <motor name="lbthigh" joint="lbthigh" gear="6" ctrlrange="-1 1" forcerange="-2.83 2.83" />
    <motor name="lbshin" joint="lbshin" gear="6" ctrlrange="-1 1" forcerange="-2.83 2.83" />
    <motor name="rbthigh" joint="rbthigh" gear="6" ctrlrange="-1 1" forcerange="-2.83 2.83" />
    <motor name="rbshin" joint="rbshin" gear="6" ctrlrange="-1 1" forcerange="-2.83 2.83" /> -->

    <!-- <motor gear="20" joint="lfthigh" name="lfthigh" ctrlrange="-1 1"/>
    <motor gear="20" joint="lfshin" name="lfshin" ctrlrange="-1 1"/>
    <motor gear="20" joint="rfthigh" name="rfthigh" ctrlrange="-1 1"/>
    <motor gear="20" joint="rfshin" name="rfshin" ctrlrange="-1 1"/>
    <motor gear="20" joint="lbthigh" name="lbthigh" ctrlrange="-1 1"/>
    <motor gear="20" joint="lbshin" name="lbshin" ctrlrange="-1 1"/>
    <motor gear="20" joint="rbthigh" name="rbthigh" ctrlrange="-1 1"/>
    <motor gear="20" joint="rbshin" name="rbshin" ctrlrange="-1 1"/> -->
    <motor gear="1" joint="lfthigh" name="lfthigh" ctrlrange="-20 20"/>
    <motor gear="1" joint="lfshin" name="lfshin" ctrlrange="-20 20"/>
    <motor gear="1" joint="rfthigh" name="rfthigh" ctrlrange="-20 20"/>
    <motor gear="1" joint="rfshin" name="rfshin" ctrlrange="-20 20"/>
    <motor gear="1" joint="lbthigh" name="lbthigh" ctrlrange="-20 20"/>
    <motor gear="1" joint="lbshin" name="lbshin" ctrlrange="-20 20"/>
    <motor gear="1" joint="rbthigh" name="rbthigh" ctrlrange="-20 20"/>
    <motor gear="1" joint="rbshin" name="rbshin" ctrlrange="-20 20"/>
  </actuator>
</mujoco>