<mujoco model="cheetah">
  <!-- <compiler angle="radian" coordinate="local" inertiafromgeom="true" settotalmass="10"/> -->
  <compiler angle="radian" coordinate="local" inertiafromgeom="true" settotalmass="20"/>

  <default>
    <joint armature=".1" damping=".01" limited="true" solimplimit="0 .8 .03" solreflimit=".02 1" stiffness="8"/>
    <geom conaffinity="0" condim="3" contype="1" friction=".4 .1 .1" rgba="0.8 0.6 .4 1" solimp="0.0 0.8 0.01" solref="0.02 1"/>
    <!-- <motor ctrllimited="true" ctrlrange="-1 1"/> -->
  </default>
  <size nstack="300000" nuser_geom="1"/>
  <option gravity="0 0 -9.81" timestep="0.01"/>
  <!-- <option gravity="0 0 0" timestep="0.01"/> -->

  <asset>
    <texture builtin="gradient" height="100" rgb1="1 1 1" rgb2="0 0 0" type="skybox" width="100"/>
    <texture builtin="flat" height="1278" mark="cross" markrgb="1 1 1" name="texgeom" random="0.01" rgb1="0.8 0.6 0.4" rgb2="0.8 0.6 0.4" type="cube" width="127"/>
    <texture builtin="checker" height="100" name="texplane" rgb1="0 0 0" rgb2="0.8 0.8 0.8" type="2d" width="100"/>
    <material name="MatPlane" reflectance="0.5" shininess="1" specular="1" texrepeat="60 60" texture="texplane"/>
    <material name="geom" texture="texgeom" texuniform="true"/>
  </asset>
  <worldbody>
    <light cutoff="100" diffuse="1 1 1" dir="-0 0 -1.3" directional="true" exponent="1" pos="0 0 1.3" specular=".1 .1 .1"/>
    <geom conaffinity="1" condim="6" material="MatPlane" name="floor" pos="0 0 0" rgba="0.8 0.9 0.8 1" size="40 40 40" type="plane"/>
    <body name="torso" pos="0 0 .7">
      <camera name="track" mode="trackcom" pos="0 -3 0.3" xyaxes="1 0 0 0 0 1"/>
      <joint armature="0" axis="1 0 0" damping="0" limited="false" name="rootx" pos="0 0 0" stiffness="0" type="slide"/>
      <joint armature="0" axis="0 0 1" damping="0" limited="false" name="rootz" pos="0 0 0" stiffness="0" type="slide"/>
      <joint armature="0" axis="0 1 0" damping="0" limited="false" name="rooty" pos="0 0 0" stiffness="0" type="hinge"/>
      <geom fromto="-.4 0 0 0 0 0" name="torso1" size="0.046" type="capsule"/>
      
      <body name="bthigh" pos="-.4 0 0">
        <joint axis="0 1 0" damping="6" name="bthigh" pos="0 0 0" range="-.52 1.05" stiffness="180" type="hinge"/>
        <geom axisangle="0 1 0 -3.8" name="bthigh_geom" pos=".1 0 -.13" size="0.046 .145" type="capsule"/>
        <body name="bshin" pos=".16 0 -.25">
          <joint axis="0 1 0" damping="4.5" name="bshin" pos="0 0 0" range="-.785 .785" stiffness="120" type="hinge"/>
          <geom axisangle="0 1 0 -2.03" name="bshin_geom" pos="-.14 0 -.07" rgba="0.9 0.6 0.6 1" size="0.046 .15" type="capsule"/>
          <site name="back_contact" type="box" size="0.05 0.05" rgba="0 1 0 1" pos="-.29 0 -.18"/>
          <body name="bfoot" pos="-.28 0 -.14">
          </body>
        </body>
      </body>

      <body name="midtorso" pos="0 0 0">
        <joint axis="0 1 0" name="midtorso_joint" pos="0 0 0" range="-0.5 0.5" type="hinge" stiffness="100"/>
        <geom fromto="0 0 0 .4 0 0" name="torso2" size="0.046" type="capsule"/>

        <body name="fthigh" pos=".4 0 0">
          <joint axis="0 1 0" damping="4.5" name="fthigh" pos="0 0 0" range="-1 .7" stiffness="180" type="hinge"/>
          <geom axisangle="0 1 0 .52" name="fthigh_geom" pos="-.07 0 -.12" size="0.046 .133" type="capsule"/>
          <body name="fshin" pos="-.14 0 -.24">
            <joint axis="0 1 0" damping="3" name="fshin" pos="0 0 0" range="-1.2 .87" stiffness="120" type="hinge"/>
            <geom axisangle="0 1 0 -.6" name="fshin_geom" pos=".065 0 -.09" rgba="0.9 0.9 0.6 0.2" size="0.046 .106" type="capsule"/>
            <site name="front_contact" type="box" size="0.05 0.05" rgba="0 1 0 1" pos=".12 0 -.22"/>
            <body name="ffoot" pos=".13 0 -.18">
            </body>
          </body>
        </body>
      </body>
    </body>
  </worldbody>
  <actuator>
    <motor gear="120" joint="bthigh" name="bthigh"/>
    <motor gear="90" joint="bshin" name="bshin"/>
    <motor gear="120" joint="fthigh" name="fthigh"/>
    <motor gear="60" joint="fshin" name="fshin"/>
    <!-- <motor gear="120" joint="midtorso_joint" name="midtorso_joint"/> -->
  </actuator>
  <sensor>
    <touch site="front_contact"/>
    <touch site="back_contact"/>
  </sensor>
</mujoco>
