<mujoco model="cheetah">
  <compiler angle="radian" coordinate="local" inertiafromgeom="true" settotalmass="4.5"/>
  <default>
    <joint armature=".01" damping="3" limited="true" frictionloss="0.2" stiffness="8"/>
    <geom conaffinity="0" condim="3" contype="1" friction="1.5 .1 .1" rgba="0.8 0.6 .4 1" solimp="0.0 0.8 0.01" solref="0.02 1"/>
    <motor ctrllimited="true" ctrlrange="-1 1"/>
  </default>
  <size nstack="300000" nuser_geom="1"/>
  <option gravity="0 0 -9.81" timestep="0.01"/>
  <asset>
    <texture builtin="gradient" height="100" rgb1="1 1 1" rgb2="0 0 0" type="skybox" width="100"/>
    <texture builtin="flat" height="1278" mark="cross" markrgb="1 1 1" name="texgeom" random="0.01" rgb1="0.8 0.6 0.4" rgb2="0.8 0.6 0.4" type="cube" width="127"/>
    <texture builtin="checker" height="100" name="texplane" rgb1="0 0 0" rgb2="0.8 0.8 0.8" type="2d" width="100"/>
    <material name="MatPlane" reflectance="0.5" shininess="1" specular="1" texrepeat="60 60" texture="texplane"/>
    <material name="geom" texture="texgeom" texuniform="true"/>
  </asset>
  <worldbody>
    <light cutoff="100" diffuse="1 1 1" dir="-0 0 -1.3" directional="true" exponent="1" pos="0 0 1.3" specular=".1 .1 .1"/>
    <geom conaffinity="1" condim="3" material="MatPlane" name="floor" pos="0 0 0" rgba="0.8 0.9 0.8 1" size="40 40 40" type="plane"/>
    <body name="torso" pos="0 0 .17">
      <camera name="track" mode="trackcom" pos="0 -3 0.3" xyaxes="1 0 0 0 0 1"/>
      <joint armature="0" axis="1 0 0" damping="0" limited="false" name="rootx" pos="0 0 0" stiffness="0" type="slide"/>
      <joint armature="0" axis="0 0 1" damping="0" limited="false" name="rootz" pos="0 0 0" stiffness="0" type="slide"/>
      <joint armature="0" axis="0 1 0" damping="0" limited="false" name="rooty" pos="0 0 0" stiffness="0" type="hinge"/>
      <geom fromto="-.15 0 0 .15 0 0" name="torso" size="0.02" type="capsule"/>

      <!-- Left front leg -->
      <body name="lfthigh" pos=".15 0.04 0">
        <joint axis="0 1 0" name="lfthigh" pos="0 0 0" range="-1 .7" type="hinge"/>
        <geom axisangle="0 1 0 .78" name="lfthigh" pos="-.03535 0 -.03535" size="0.02 .05" type="capsule"/>
        <body name="lfshin" pos="-.0707 0 -.0707">
          <joint axis="0 1 0" name="lfshin" pos="0 0 0" range="-1.2 .87" type="hinge"/>
          <geom axisangle="0 1 0 -.78" name="lfshin" pos=".03535 0 -.03535" rgba="0.9 0.6 0.6 1" size="0.02 .05" type="capsule"/>
        </body>
      </body>

      <!-- Right front leg -->
      <body name="rfthigh" pos=".15 -0.04 0">
        <joint axis="0 1 0" name="rfthigh" pos="0 0 0" range="-1 .7" type="hinge"/>
        <geom axisangle="0 1 0 .78" name="rfthigh" pos="-.03535 0 -.03535" size="0.02 .05" type="capsule"/>
        <body name="rfshin" pos="-.0707 0 -.0707">
          <joint axis="0 1 0" name="rfshin" pos="0 0 0" range="-1.2 .87" type="hinge"/>
          <geom axisangle="0 1 0 -.78" name="rfshin" pos=".03535 0 -.03535" rgba="0.9 0.6 0.6 1" size="0.02 .05" type="capsule"/>
        </body>
      </body>

      <body name="lbthigh" pos="-.15 0.04 0">
        <joint axis="0 1 0" name="lbthigh" pos="0 0 0" range="-1 .7" type="hinge"/>
        <geom axisangle="0 1 0 .78" name="lbthigh" pos="-.03535 0 -.03535" size="0.02 .05" type="capsule"/>
        <body name="lbshin" pos="-.0707 0 -.0707">
          <joint axis="0 1 0" name="lbshin" pos="0 0 0" range="-1.2 .87" type="hinge"/>
          <geom axisangle="0 1 0 -.78" name="lbshin" pos=".03535 0 -.03535" rgba="0.9 0.6 0.6 1" size="0.02 .05" type="capsule"/>
        </body>
      </body>

      <body name="rbthigh" pos="-.15 -0.04 0">
        <joint axis="0 1 0" name="rbthigh" pos="0 0 0" range="-1 .7" type="hinge"/>
        <geom axisangle="0 1 0 .78" name="rbthigh" pos="-.03535 0 -.03535" size="0.02 .05" type="capsule"/>
        <body name="rbshin" pos="-.0707 0 -.0707">
          <joint axis="0 1 0" name="rbshin" pos="0 0 0" range="-1.2 .87" type="hinge"/>
          <geom axisangle="0 1 0 -.78" name="rbshin" pos=".03535 0 -.03535" rgba="0.9 0.6 0.6 1" size="0.02 .05" type="capsule"/>
        </body>
      </body>
    </body>
  </worldbody>
  <actuator>
    <motor gear="1" joint="lfthigh" name="lfthigh" ctrlrange="-10 10"/>
    <motor gear="1" joint="lfshin" name="lfshin" ctrlrange="-10 10"/>
    <motor gear="1" joint="rfthigh" name="rfthigh" ctrlrange="-10 10"/>
    <motor gear="1" joint="rfshin" name="rfshin" ctrlrange="-10 10"/>
    <motor gear="1" joint="lbthigh" name="lbthigh" ctrlrange="-10 10"/>
    <motor gear="1" joint="lbshin" name="lbshin" ctrlrange="-10 10"/>
    <motor gear="1" joint="rbthigh" name="rbthigh" ctrlrange="-10 10"/>
    <motor gear="1" joint="rbshin" name="rbshin" ctrlrange="-10 10"/>
  </actuator>
</mujoco>